Workbook

Sheet Pivot Analysis
A3: Row Labels | B3: Count of Loan_ID
A4: Active | B4: 128
A5: Closed | B5: 142
A6: Defaulted | B6: 120
A7: Overdue | B7: 110
A8: Grand Total | B8: 500

Sheet Pivot Loan Purpose Analysis
A3: Row Labels | B3: Count of Loan_ID | C3: Sum of Loan_Amount | D3: Sum of Default_Flag
A4: Business | B4: 86 | C4: 98161861 | D4: 26
A5: Education | B5: 80 | C5: 74740654 | D5: 21
A6: Home | B6: 83 | C6: 81494659 | D6: 26
A7: Medical | B7: 88 | C7: 89416780 | D7: 33
A8: Personal | B8: 72 | C8: 76587650 | D8: 13
A9: Vehicle | B9: 91 | C9: 89467004 | D9: 29
A10: (blank)
A11: Grand Total | B11: 500 | C11: 509868608 | D11: 148

Sheet Pivot Employment
A3: Row Labels | B3: Count of Loan_ID | C3: Sum of Default_Flag
A4: Business | B4: 158 | C4: 53
A5: Salaried | B5: 173 | C5: 42
A6: Self-Employed | B6: 169 | C6: 53
A7: (blank)
A8: Grand Total | B8: 500 | C8: 148

Sheet Pivot Region
A3: Row Labels | B3: Count of Loan_ID | C3: Sum of Loan_Amount | D3: Sum of Default_Flag
A4: Central | B4: 101 | C4: 101045606 | D4: 31
A5: East | B5: 105 | C5: 100109383 | D5: 36
A6: North | B6: 112 | C6: 124757941 | D6: 31
A7: South | B7: 96 | C7: 104842843 | D7: 20
A8: West | B8: 86 | C8: 79112835 | D8: 30
A9: (blank)
A10: Grand Total | B10: 500 | C10: 509868608 | D10: 148

Sheet Pivot Credit Score
A3: Row Labels | B3: Count of Loan_ID | C3: Sum of Default_Flag
A4: Excellent | B4: 99 | C4: 17
A5: Fair | B5: 82 | C5: 15
A6: Good | B6: 58 | C6: 8
A7: Poor | B7: 261 | C7: 108
A8: (blank)
A9: Grand Total | B9: 500 | C9: 148

Sheet Pivot DTI
A3: Row Labels | B3: Count of Loan_ID | C3: Sum of Default_Flag
A4: High | B4: 212 | C4: 87
A5: Low | B5: 99 | C5: 27
A6: Medium | B6: 189 | C6: 34
A7: (blank)
A8: Grand Total | B8: 500 | C8: 148

Sheet Pivot Monthly
A3: Row Labels | B3: Count of Loan_ID | C3: Sum of Loan_Amount
A4: <1/5/2023
A5: 2023 | B5: 168 | C5: 156558658
A6: 2024 | B6: 181 | C6: 186219333
A7: 2025 | B7: 151 | C7: 167090617
A8: Grand Total | B8: 500 | C8: 509868608

Sheet Pivot Status Amount
A3: Row Labels | B3: Count of Loan_ID | C3: Sum of Loan_Amount
A4: Active | B4: 128 | C4: 134495830
A5: Closed | B5: 142 | C5: 142413163
A6: Defaulted | B6: 120 | C6: 127649351
A7: Overdue | B7: 110 | C7: 105310264
A8: (blank)
A9: Grand Total | B9: 500 | C9: 509868608

Sheet Pivot Purpose Amount
A3: Row Labels | B3: Count of Loan_ID | C3: Sum of Loan_Amount
A4: Business | B4: 86 | C4: 98161861
A5: Education | B5: 80 | C5: 74740654
A6: Home | B6: 83 | C6: 81494659
A7: Medical | B7: 88 | C7: 89416780
A8: Personal | B8: 72 | C8: 76587650
A9: Vehicle | B9: 91 | C9: 89467004
A10: (blank)
A11: Grand Total | B11: 500 | C11: 509868608

Sheet Working Data
A1: Loan_ID | B1: Application_Date | C1: Customer_Age | D1: Employment_Type | E1: Annual_Income | F1: Credit_Score | G1: Loan_Amount | H1: Interest_Rate | I1: Loan_Term_Months | J1: Loan_Purpose | K1: Debt_to_Income | L1: Region | M1: Loan_Status | N1: Default_Flag | O1: Credit_Score_Band | P1: DTI_Band
A2: LN0001 | B2: 45247 | C2: 65 | D2: Salaried | E2: 1459358 | F2: 434 | G2: 1730164 | H2: 9 | I2: 24 | J2: Education | K2: 0.22 | L2: North | M2: Closed | N2: 0 | O2: =IF(F2<580,"Poor",IF(F2<670,"Fair",IF(F2<740,"Good","Excellent"))) -> Poor | P2: =IF(K2<0.2,"Low",IF(K2<0.4,"Medium","High")) -> Medium
A3: LN0002 | B3: 45868 | C3: 27 | D3: Salaried | E3: 1383991 | F3: 315 | G3: 1604874 | H3: 21 | I3: 60 | J3: Personal | K3: 0.39 | L3: Central | M3: Defaulted | N3: 1 | O3: =IF(F3<580,"Poor",IF(F3<670,"Fair",IF(F3<740,"Good","Excellent"))) -> Poor | P3: =IF(K3<0.2,"Low",IF(K3<0.4,"Medium","High")) -> Medium
A4: LN0003 | B4: 45506 | C4: 64 | D4: Business | E4: 979635 | F4: 786 | G4: 1096480 | H4: 7 | I4: 60 | J4: Home | K4: 0.12 | L4: West | M4: Defaulted | N4: 0 | O4: =IF(F4<580,"Poor",IF(F4<670,"Fair",IF(F4<740,"Good","Excellent"))) -> Excellent | P4: =IF(K4<0.2,"Low",IF(K4<0.4,"Medium","High")) -> Low
A5: LN0004 | B5: 45280 | C5: 65 | D5: Salaried | E5: 1482614 | F5: 580 | G5: 218134 | H5: 17 | I5: 12 | J5: Business | K5: 0.36 | L5: West | M5: Overdue | N5: 0 | O5: =IF(F5<580,"Poor",IF(F5<670,"Fair",IF(F5<740,"Good","Excellent"))) -> Fair | P5: =IF(K5<0.2,"Low",IF(K5<0.4,"Medium","High")) -> Medium
A6: LN0005 | B6: 45323 | C6: 65 | D6: Self-Employed | E6: 2227831 | F6: 315 | G6: 1396820 | H6: 12 | I6: 24 | J6: Vehicle | K6: 0.48 | L6: North | M6: Defaulted | N6: 0 | O6: =IF(F6<580,"Poor",IF(F6<670,"Fair",IF(F6<740,"Good","Excellent"))) -> Poor | P6: =IF(K6<0.2,"Low",IF(K6<0.4,"Medium","High")) -> High
A7: LN0006 | B7: 45322 | C7: 57 | D7: Business | E7: 1312014 | F7: 694 | G7: 736968 | H7: 23 | I7: 36 | J7: Personal | K7: 0.53 | L7: East | M7: Defaulted | N7: 0 | O7: =IF(F7<580,"Poor",IF(F7<670,"Fair",IF(F7<740,"Good","Excellent"))) -> Good | P7: =IF(K7<0.2,"Low",IF(K7<0.4,"Medium","High")) -> High
A8: LN0007 | B8: 45293 | C8: 50 | D8: Salaried | E8: 1584239 | F8: 806 | G8: 1432594 | H8: 18 | I8: 36 | J8: Vehicle | K8: 0.56 | L8: North | M8: Overdue | N8: 0 | O8: =IF(F8<580,"Poor",IF(F8<670,"Fair",IF(F8<740,"Good","Excellent"))) -> Excellent | P8: =IF(K8<0.2,"Low",IF(K8<0.4,"Medium","High")) -> High
A9: LN0008 | B9: 45541 | C9: 37 | D9: Business | E9: 799794 | F9: 824 | G9: 464708 | H9: 14 | I9: 24 | J9: Education | K9: 0.28 | L9: North | M9: Closed | N9: 0 | O9: =IF(F9<580,"Poor",IF(F9<670,"Fair",IF(F9<740,"Good","Excellent"))) -> Excellent | P9: =IF(K9<0.2,"Low",IF(K9<0.4,"Medium","High")) -> Medium
A10: LN0009 | B10: 45998 | C10: 39 | D10: Business | E10: 2170628 | F10: 440 | G10: 1455451 | H10: 16 | I10: 12 | J10: Vehicle | K10: 0.58 | L10: East | M10: Defaulted | N10: 1 | O10: =IF(F10<580,"Poor",IF(F10<670,"Fair",IF(F10<740,"Good","Excellent"))) -> Poor | P10: =IF(K10<0.2,"Low",IF(K10<0.4,"Medium","High")) -> High
A11: LN0010 | B11: 45585 | C11: 47 | D11: Business | E11: 1992137 | F11: 763 | G11: 894268 | H11: 17 | I11: 36 | J11: Medical | K11: 0.37 | L11: West | M11: Overdue | N11: 1 | O11: =IF(F11<580,"Poor",IF(F11<670,"Fair",IF(F11<740,"Good","Excellent"))) -> Excellent | P11: =IF(K11<0.2,"Low",IF(K11<0.4,"Medium","High")) -> Medium
A12: LN0011 | B12: 44943 | C12: 51 | D12: Salaried | E12: 737473 | F12: 693 | G12: 330315 | H12: 16 | I12: 36 | J12: Personal | K12: 0.52 | L12: Central | M12: Closed | N12: 0 | O12: =IF(F12<580,"Poor",IF(F12<670,"Fair",IF(F12<740,"Good","Excellent"))) -> Good | P12: =IF(K12<0.2,"Low",IF(K12<0.4,"Medium","High")) -> High
A13: LN0012 | B13: 45375 | C13: 35 | D13: Business | E13: 1725813 | F13: 798 | G13: 1922714 | H13: 14 | I13: 24 | J13: Business | K13: 0.54 | L13: South | M13: Closed | N13: 0 | O13: =IF(F13<580,"Poor",IF(F13<670,"Fair",IF(F13<740,"Good","Excellent"))) -> Excellent | P13: =IF(K13<0.2,"Low",IF(K13<0.4,"Medium","High")) -> High
... A501: LN0500 | B501: 45781 | C501: 54 | D501: Self-Employed | E501: 1260831 | F501: 447 | G501: 351589 | H501: 7 | I501: 12 | J501: Vehicle | K501: 0.31 | L501: North | M501: Active | N501: 1 | O501: =IF(F501<580,"Poor",IF(F501<670,"Fair",IF(F501<740,"Good","Excellent"))) -> Poor | P501: =IF(K501<0.2,"Low",IF(K501<0.4,"Medium","High")) -> Medium

Sheet Analysis
A1: Portfolio KPIs | D1: Risk Summary
A3: Total Loan Amount | B3: =SUM('Working Data'!G2:G501) -> 509868608 | D3: Defaulted Loans | E3: =B11 -> 148
A4: Total Number of Loans | B4: =COUNTA('Working Data'!A2:A501) -> 500 | D4: Default Rate | E4: =B10 -> 0.296
A5: Average Loan Amount | B5: =AVERAGE('Working Data'!G2:G501) -> 1019737.2 | D5: Overdue Loans | E5: =B14 -> 110
A6: Average Interest Rate | B6: =AVERAGE('Working Data'!H2:H501) -> 15.044 | D6: Overdue Loan % | E6: =B18 -> 0.22
A7: Average Credit Score | B7: =AVERAGE('Working Data'!F2:F501) -> 571.334
A8: Average Annual Income | B8: =AVERAGE('Working Data'!E2:E501) -> 1301532
A9: Average Debt-to-Income Ratio | B9: =AVERAGE('Working Data'!K2:K501) -> 0.35318
A10: Default Rate | B10: =AVERAGE('Working Data'!N2:N501) -> 0.296 | D10: Loan Purpose | E10: Number of Loans | F10: Total Loan Amount | G10: Defaulted Loans | H10: Default Rate | I10: Average Loan Amount
A11: Defaulted Loans | B11: =COUNTIF('Working Data'!N2:N501,1) -> 148 | D11: Home | E11: =COUNTIF('Working Data'!J:J,D11) -> 83 | F11: =SUMIF('Working Data'!J:J,D11,'Working Data'!G:G) -> 81494659 | G11: =SUMIF('Working Data'!J:J,D11,'Working Data'!N:N) -> 26 | H11: =G11/E11 -> 0.31325301 | I11: =F11/E11 -> 981863.36
A12: Closed Loans | B12: =COUNTIF('Working Data'!M2:M501,"Closed") -> 142 | D12: Education | E12: =COUNTIF('Working Data'!J:J,D12) -> 80 | F12: =SUMIF('Working Data'!J:J,D12,'Working Data'!G:G) -> 74740654 | G12: =SUMIF('Working Data'!J:J,D12,'Working Data'!N:N) -> 21 | H12: =G12/E12 -> 0.2625 | I12: =F12/E12 -> 934258.18
A13: Active Loans | B13: =COUNTIF('Working Data'!M2:M501,"Active") -> 128 | D13: Medical | E13: =COUNTIF('Working Data'!J:J,D13) -> 88 | F13: =SUMIF('Working Data'!J:J,D13,'Working Data'!G:G) -> 89416780 | G13: =SUMIF('Working Data'!J:J,D13,'Working Data'!N:N) -> 33 | H13: =G13/E13 -> 0.375 | I13: =F13/E13 -> 1016099.8
A14: Overdue Loans | B14: =COUNTIF('Working Data'!M2:M501,"Overdue") -> 110 | D14: Business | E14: =COUNTIF('Working Data'!J:J,D14) -> 86 | F14: =SUMIF('Working Data'!J:J,D14,'Working Data'!G:G) -> 98161861 | G14: =SUMIF('Working Data'!J:J,D14,'Working Data'!N:N) -> 26 | H14: =G14/E14 -> 0.30232558 | I14: =F14/E14 -> 1141417
A15: Total Status Count | B15: =COUNTIF('Working Data'!M2:M501,"Active")+COUNTIF('Working Data'!M2:M501,"Closed")+COUNTIF('Working Data'!M2:M501,"Overdue")+COUNTIF('Working Data'!M2:M501,"Defaulted") -> 500 | D15: Vehicle | E15: =COUNTIF('Working Data'!J:J,D15) -> 91 | F15: =SUMIF('Working Data'!J:J,D15,'Working Data'!G:G) -> 89467004 | G15: =SUMIF('Working Data'!J:J,D15,'Working Data'!N:N) -> 29 | H15: =G15/E15 -> 0.31868132 | I15: =F15/E15 -> 983153.89
A16: Closed Loan % | B16: =B12/$B$15 -> 0.284 | D16: Personal | E16: =COUNTIF('Working Data'!J:J,D16) -> 72 | F16: =SUMIF('Working Data'!J:J,D16,'Working Data'!G:G) -> 76587650 | G16: =SUMIF('Working Data'!J:J,D16,'Working Data'!N:N) -> 13 | H16: =G16/E16 -> 0.18055556 | I16: =F16/E16 -> 1063717.4
A17: Active Loan % | B17: =B13/$B$15 -> 0.256
A18: Overdue Loan % | B18: =B14/$B$15 -> 0.22 | D18: Highest Default Rate | E18: =MAX(H11:H16) -> 0.375
A19: Defaulted Loan % | B19: =B11/$B$15 -> 0.296 | D19: Loan Purpose with Highest Default Rate | E19: =INDEX(D11:D16,MATCH(E18,H11:H16,0)) -> Medical
D21: Employment Type Risk Analysis | E21: Number of Loans | F21: Defaulted Loans | G21: Default Rate
D23: Employment Type
D24: Salaried | E24: =COUNTIF('Working Data'!D:D,D24) -> 173 | F24: =SUMIF('Working Data'!D:D,D24,'Working Data'!N:N) -> 42 | G24: =F24/E24 -> 0.24277457
D25: Self-Employed | E25: =COUNTIF('Working Data'!D:D,D25) -> 169 | F25: =SUMIF('Working Data'!D:D,D25,'Working Data'!N:N) -> 53 | G25: =F25/E25 -> 0.31360947
D26: Business | E26: =COUNTIF('Working Data'!D:D,D26) -> 158 | F26: =SUMIF('Working Data'!D:D,D26,'Working Data'!N:N) -> 53 | G26: =F26/E26 -> 0.33544304
D29: Regional Risk Analysis
D31: Region | E31: Number of Loans | F31: Total Loan Amount | G31: Defaulted Loans | H31: Default Rate
D32: North | E32: =COUNTIF('Working Data'!L:L,D32) -> 112 | F32: =SUMIF('Working Data'!L:L,D32,'Working Data'!G:G) -> 124757941 | G32: =SUMIF('Working Data'!L:L,D32,'Working Data'!N:N) -> 31 | H32: =G32/E32 -> 0.27678571
D33: South | E33: =COUNTIF('Working Data'!L:L,D33) -> 96 | F33: =SUMIF('Working Data'!L:L,D33,'Working Data'!G:G) -> 104842843 | G33: =SUMIF('Working Data'!L:L,D33,'Working Data'!N:N) -> 20 | H33: =G33/E33 -> 0.20833333
D34: East | E34: =COUNTIF('Working Data'!L:L,D34) -> 105 | F34: =SUMIF('Working Data'!L:L,D34,'Working Data'!G:G) -> 100109383 | G34: =SUMIF('Working Data'!L:L,D34,'Working Data'!N:N) -> 36 | H34: =G34/E34 -> 0.34285714
D35: West | E35: =COUNTIF('Working Data'!L:L,D35) -> 86 | F35: =SUMIF('Working Data'!L:L,D35,'Working Data'!G:G) -> 79112835 | G35: =SUMIF('Working Data'!L:L,D35,'Working Data'!N:N) -> 30 | H35: =G35/E35 -> 0.34883721
D36: Central | E36: =COUNTIF('Working Data'!L:L,D36) -> 101 | F36: =SUMIF('Working Data'!L:L,D36,'Working Data'!G:G) -> 101045606 | G36: =SUMIF('Working Data'!L:L,D36,'Working Data'!N:N) -> 31 | H36: =G36/E36 -> 0.30693069
D39: Credit Score Risk Analysis
D41: Credit Score Band | E41: Number of Loans | F41: Defaulted Loans | G41: Default Rate
D42: Poor | E42: =COUNTIF('Working Data'!O:O,D42) -> 261 | F42: =SUMIF('Working Data'!O:O,D42,'Working Data'!N:N) -> 108 | G42: =F42/E42 -> 0.4137931
D43: Fair | E43: =COUNTIF('Working Data'!O:O,D43) -> 82 | F43: =SUMIF('Working Data'!O:O,D43,'Working Data'!N:N) -> 15 | G43: =F43/E43 -> 0.18292683
D44: Good | E44: =COUNTIF('Working Data'!O:O,D44) -> 58 | F44: =SUMIF('Working Data'!O:O,D44,'Working Data'!N:N) -> 8 | G44: =F44/E44 -> 0.13793103
D45: Excellent | E45: =COUNTIF('Working Data'!O:O,D45) -> 99 | F45: =SUMIF('Working Data'!O:O,D45,'Working Data'!N:N) -> 17 | G45: =F45/E45 -> 0.17171717
D48: DTI Risk Analysis
D50: DTI Band | E50: Number of Loans | F50: Defaulted Loans | G50: Default Rate
D51: Low | E51: =COUNTIF('Working Data'!P:P,D51) -> 99 | F51: =SUMIF('Working Data'!P:P,D51,'Working Data'!N:N) -> 27 | G51: =F51/E51 -> 0.27272727
D52: Medium | E52: =COUNTIF('Working Data'!P:P,D52) -> 189 | F52: =SUMIF('Working Data'!P:P,D52,'Working Data'!N:N) -> 34 | G52: =F52/E52 -> 0.17989418
...

Sheet Raw Data
A1: Loan_ID | B1: Application_Date | C1: Customer_Age | D1: Employment_Type | E1: Annual_Income | F1: Credit_Score | G1: Loan_Amount | H1: Interest_Rate | I1: Loan_Term_Months | J1: Loan_Purpose | K1: Debt_to_Income | L1: Region | M1: Loan_Status | N1: Default_Flag
A2: LN0001 | B2: 45247 | C2: 65 | D2: Salaried | E2: 1459358 | F2: 434 | G2: 1730164 | H2: 9 | I2: 24 | J2: Education | K2: 0.22 | L2: North | M2: Closed | N2: 0
A3: LN0002 | B3: 45868 | C3: 27 | D3: Salaried | E3: 1383991 | F3: 315 | G3: 1604874 | H3: 21 | I3: 60 | J3: Personal | K3: 0.39 | L3: Central | M3: Defaulted | N3: 1
A4: LN0003 | B4: 45506 | C4: 64 | D4: Business | E4: 979635 | F4: 786 | G4: 1096480 | H4: 7 | I4: 60 | J4: Home | K4: 0.12 | L4: West | M4: Defaulted | N4: 0
A5: LN0004 | B5: 45280 | C5: 65 | D5: Salaried | E5: 1482614 | F5: 580 | G5: 218134 | H5: 17 | I5: 12 | J5: Business | K5: 0.36 | L5: West | M5: Overdue | N5: 0
A6: LN0005 | B6: 45323 | C6: 65 | D6: Self-Employed | E6: 2227831 | F6: 315 | G6: 1396820 | H6: 12 | I6: 24 | J6: Vehicle | K6: 0.48 | L6: North | M6: Defaulted | N6: 0
A7: LN0006 | B7: 45322 | C7: 57 | D7: Business | E7: 1312014 | F7: 694 | G7: 736968 | H7: 23 | I7: 36 | J7: Personal | K7: 0.53 | L7: East | M7: Defaulted | N7: 0
A8: LN0007 | B8: 45293 | C8: 50 | D8: Salaried | E8: 1584239 | F8: 806 | G8: 1432594 | H8: 18 | I8: 36 | J8: Vehicle | K8: 0.56 | L8: North | M8: Overdue | N8: 0
A9: LN0008 | B9: 45541 | C9: 37 | D9: Business | E9: 799794 | F9: 824 | G9: 464708 | H9: 14 | I9: 24 | J9: Education | K9: 0.28 | L9: North | M9: Closed | N9: 0
A10: LN0009 | B10: 45998 | C10: 39 | D10: Business | E10: 2170628 | F10: 440 | G10: 1455451 | H10: 16 | I10: 12 | J10: Vehicle | K10: 0.58 | L10: East | M10: Defaulted | N10: 1
A11: LN0010 | B11: 45585 | C11: 47 | D11: Business | E11: 1992137 | F11: 763 | G11: 894268 | H11: 17 | I11: 36 | J11: Medical | K11: 0.37 | L11: West | M11: Overdue | N11: 1
A12: LN0011 | B12: 44943 | C12: 51 | D12: Salaried | E12: 737473 | F12: 693 | G12: 330315 | H12: 16 | I12: 36 | J12: Personal | K12: 0.52 | L12: Central | M12: Closed | N12: 0
A13: LN0012 | B13: 45375 | C13: 35 | D13: Business | E13: 1725813 | F13: 798 | G13: 1922714 | H13: 14 | I13: 24 | J13: Business | K13: 0.54 | L13: South | M13: Closed | N13: 0
... A501: LN0500 | B501: 45781 | C501: 54 | D501: Self-Employed | E501: 1260831 | F501: 447 | G501: 351589 | H501: 7 | I501: 12 | J501: Vehicle | K501: 0.31 | L501: North | M501: Active | N501: 1

Sheet Dashboard
A1: Bank Loan Portfolio & Credit Risk Analysis
A2: Synthetic loan portfolio dataset | Credit risk analysis
A3: Total Loan Amount | C3: Total Loans | E3: Average Loan Amount | G3: Default Rate
A4: =Analysis!B3 -> 509868608 | C4: =Analysis!B4 -> 500 | E4: =Analysis!B5 -> 1019737.2 | G4: =Analysis!B10 -> 0.296
A6: Defaulted Loans | C6: Active Loans | E6: Overdue Loans | G6: Closed Loans
A7: =Analysis!B11 -> 148 | C7: =Analysis!B13 -> 128 | E7: =Analysis!B14 -> 110 | G7: =Analysis!B12 -> 142
A9: Loan Status | B9: Number of Loans | D9: Loan Purpose | E9: Number of Loans
A10: Active | B10: =Analysis!E59 -> 128 | D10: Home | E10: =Analysis!E11 -> 83
A11: Closed | B11: =Analysis!E60 -> 142 | D11: Education | E11: =Analysis!E12 -> 80
A12: Overdue | B12: =Analysis!E61 -> 110 | D12: Medical | E12: =Analysis!E13 -> 88
A13: Defaulted | B13: =Analysis!E62 -> 120 | D13: Business | E13: =Analysis!E14 -> 86
D14: Vehicle | E14: =Analysis!E15 -> 91
D15: Personal | E15: =Analysis!E16 -> 72
D18: Credit Score Band | E18: Default Rate | G18: DTI Band | H18: Default Rate
D19: Poor | E19: =Analysis!G42 -> 0.4137931 | G19: Low | H19: =Analysis!G51 -> 0.27272727
D20: Fair | E20: =Analysis!G43 -> 0.18292683 | G20: Medium | H20: =Analysis!G52 -> 0.17989418
D21: Good | E21: =Analysis!G44 -> 0.13793103 | G21: High | H21: =Analysis!G53 -> 0.41037736
D22: Excellent | E22: =Analysis!G45 -> 0.17171717
A85: Analysis Period: 2023–2025
